Fetching AP Data
Running fetch_ap_data.py...
Fetching data from 2024-07-24T07:00:00Z to 2024-07-25T00:00:00Z with 900 second intervals...
Bucket: aruba, Measurement: adjacent-ap, Fields: ['crawling-duration(ms)', 'curr-rssi']
Filtering for building: D1
An unexpected error occurred: Missing required environment variables. Please check your .env file.
Transforming Data
Running data_transformations.py...
Starting processing of data/adjacent_ap_data_20250704_102035.csv
Reading input data from data/adjacent_ap_data_20250704_102035.csv...
Traceback (most recent call last):
  File "/home/sionna/Documents/GitTest/src/ap-prediction-automation/data_transformations.py", line 315, in <module>
    main(args.input, args.floors, args.output)
  File "/home/sionna/Documents/GitTest/src/ap-prediction-automation/data_transformations.py", line 276, in main
    df = read_input_file(input_file)
         ^^^^^^^^^^^^^^^^^^^^^^^^^^^
  File "/home/sionna/Documents/GitTest/src/ap-prediction-automation/data_transformations.py", line 81, in read_input_file
    for chunk in pd.read_csv(input_file, 
                 ^^^^^^^^^^^^^^^^^^^^^^^
  File "/usr/lib/python3/dist-packages/pandas/io/parsers/readers.py", line 948, in read_csv
    return _read(filepath_or_buffer, kwds)
           ^^^^^^^^^^^^^^^^^^^^^^^^^^^^^^^
  File "/usr/lib/python3/dist-packages/pandas/io/parsers/readers.py", line 611, in _read
    parser = TextFileReader(filepath_or_buffer, **kwds)
             ^^^^^^^^^^^^^^^^^^^^^^^^^^^^^^^^^^^^^^^^^^
  File "/usr/lib/python3/dist-packages/pandas/io/parsers/readers.py", line 1448, in __init__
    self._engine = self._make_engine(f, self.engine)
                   ^^^^^^^^^^^^^^^^^^^^^^^^^^^^^^^^^
  File "/usr/lib/python3/dist-packages/pandas/io/parsers/readers.py", line 1705, in _make_engine
    self.handles = get_handle(
                   ^^^^^^^^^^^
  File "/usr/lib/python3/dist-packages/pandas/io/common.py", line 863, in get_handle
    handle = open(
             ^^^^^
FileNotFoundError: [Errno 2] No such file or directory: 'data/adjacent_ap_data_20250704_102035.csv'
Error: data_transformations.py failed. Exiting.
